reported_result/report-8/ART_TFC/output/output7.txt

Limit	1	3	4	5	4	SELL	0	---	0
NewOrderRs	Accepted
	Trades	0
	Orders	1
	Order	Limit	1	3	4	5	4	SELL	0	---	0
	Credits	7
	Credit	1	6
	Credit	2	12
	Credit	3	9
	Credit	4	6
	Credit	5	16
	Credit	6	14
	Credit	7	7
	Ownerships	7
	Ownership	1	37
	Ownership	2	12
	Ownership	3	43
	Ownership	4	18
	Ownership	5	59
	Ownership	6	74
	Ownership	7	39
	ReferencePrice	5
	StaticPriceBandLowerLimit	0.6
	StaticPriceBandUpperLimit	0.8
	TotalShares	100
	OwnershipUpperLimit	0.2
	TickSize	1
	LotSize	1
Iceberg	2	7	2	4	6	SELL	0	---	0
NewOrderRs	Accepted
	Trades	0
	Orders	2
	Order	Iceberg	2	7	2	4	6	SELL	0	---	1
	Order	Limit	1	3	4	5	4	SELL	0	---	0
	Credits	7
	Credit	1	6
	Credit	2	12
	Credit	3	9
	Credit	4	6
	Credit	5	16
	Credit	6	14
	Credit	7	7
	Ownerships	7
	Ownership	1	37
	Ownership	2	12
	Ownership	3	43
	Ownership	4	18
	Ownership	5	59
	Ownership	6	74
	Ownership	7	39
	ReferencePrice	5
	StaticPriceBandLowerLimit	0.6
	StaticPriceBandUpperLimit	0.8
	TotalShares	100
	OwnershipUpperLimit	0.2
	TickSize	1
	LotSize	1
Iceberg	3	6	3	7	4	SELL	0	---	0
NewOrderRs	Accepted
	Trades	0
	Orders	3
	Order	Iceberg	2	7	2	4	6	SELL	0	---	1
	Order	Limit	1	3	4	5	4	SELL	0	---	0
	Order	Iceberg	3	6	3	7	4	SELL	0	---	4
	Credits	7
	Credit	1	6
	Credit	2	12
	Credit	3	9
	Credit	4	6
	Credit	5	16
	Credit	6	14
	Credit	7	7
	Ownerships	7
	Ownership	1	37
	Ownership	2	12
	Ownership	3	43
	Ownership	4	18
	Ownership	5	59
	Ownership	6	74
	Ownership	7	39
	ReferencePrice	5
	StaticPriceBandLowerLimit	0.6
	StaticPriceBandUpperLimit	0.8
	TotalShares	100
	OwnershipUpperLimit	0.2
	TickSize	1
	LotSize	1
Iceberg	4	6	2	7	6	SELL	0	---	0
NewOrderRs	Accepted
	Trades	0
	Orders	4
	Order	Iceberg	2	7	2	4	6	SELL	0	---	1
	Order	Limit	1	3	4	5	4	SELL	0	---	0
	Order	Iceberg	3	6	3	7	4	SELL	0	---	4
	Order	Iceberg	4	6	2	7	6	SELL	0	---	1
	Credits	7
	Credit	1	6
	Credit	2	12
	Credit	3	9
	Credit	4	6
	Credit	5	16
	Credit	6	14
	Credit	7	7
	Ownerships	7
	Ownership	1	37
	Ownership	2	12
	Ownership	3	43
	Ownership	4	18
	Ownership	5	59
	Ownership	6	74
	Ownership	7	39
	ReferencePrice	5
	StaticPriceBandLowerLimit	0.6
	StaticPriceBandUpperLimit	0.8
	TotalShares	100
	OwnershipUpperLimit	0.2
	TickSize	1
	LotSize	1
CancelOrderRs	Accepted
	Orders	3
	Order	Iceberg	2	7	2	4	6	SELL	0	---	1
	Order	Limit	1	3	4	5	4	SELL	0	---	0
	Order	Iceberg	3	6	3	7	4	SELL	0	---	4
	Credits	7
	Credit	1	6
	Credit	2	12
	Credit	3	9
	Credit	4	6
	Credit	5	16
	Credit	6	14
	Credit	7	7
	Ownerships	7
	Ownership	1	37
	Ownership	2	12
	Ownership	3	43
	Ownership	4	18
	Ownership	5	59
	Ownership	6	74
	Ownership	7	39
	ReferencePrice	5
	StaticPriceBandLowerLimit	0.6
	StaticPriceBandUpperLimit	0.8
	TotalShares	100
	OwnershipUpperLimit	0.2
	TickSize	1
	LotSize	1
Limit	6	5	1	7	6	SELL	0	---	0
NewOrderRs	Accepted
	Trades	0
	Orders	4
	Order	Iceberg	2	7	2	4	6	SELL	0	---	1
	Order	Limit	1	3	4	5	4	SELL	0	---	0
	Order	Iceberg	3	6	3	7	4	SELL	0	---	4
	Order	Limit	6	5	1	7	6	SELL	0	---	0
	Credits	7
	Credit	1	6
	Credit	2	12
	Credit	3	9
	Credit	4	6
	Credit	5	16
	Credit	6	14
	Credit	7	7
	Ownerships	7
	Ownership	1	37
	Ownership	2	12
	Ownership	3	43
	Ownership	4	18
	Ownership	5	59
	Ownership	6	74
	Ownership	7	39
	ReferencePrice	5
	StaticPriceBandLowerLimit	0.6
	StaticPriceBandUpperLimit	0.8
	TotalShares	100
	OwnershipUpperLimit	0.2
	TickSize	1
	LotSize	1
Iceberg	7	6	3	4	7	BUY 	0	---	0
NewOrderRs	Rejected
	Trades	0
	Orders	4
	Order	Iceberg	2	7	2	4	6	SELL	0	---	1
	Order	Limit	1	3	4	5	4	SELL	0	---	0
	Order	Iceberg	3	6	3	7	4	SELL	0	---	4
	Order	Limit	6	5	1	7	6	SELL	0	---	0
	Credits	7
	Credit	1	6
	Credit	2	12
	Credit	3	9
	Credit	4	6
	Credit	5	16
	Credit	6	14
	Credit	7	7
	Ownerships	7
	Ownership	1	37
	Ownership	2	12
	Ownership	3	43
	Ownership	4	18
	Ownership	5	59
	Ownership	6	74
	Ownership	7	39
	ReferencePrice	5
	StaticPriceBandLowerLimit	0.6
	StaticPriceBandUpperLimit	0.8
	TotalShares	100
	OwnershipUpperLimit	0.2
	TickSize	1
	LotSize	1
Iceberg	8	3	1	4	4	BUY 	0	---	0
NewOrderRs	Rejected
	Trades	0
	Orders	4
	Order	Iceberg	2	7	2	4	6	SELL	0	---	1
	Order	Limit	1	3	4	5	4	SELL	0	---	0
	Order	Iceberg	3	6	3	7	4	SELL	0	---	4
	Order	Limit	6	5	1	7	6	SELL	0	---	0
	Credits	7
	Credit	1	6
	Credit	2	12
	Credit	3	9
	Credit	4	6
	Credit	5	16
	Credit	6	14
	Credit	7	7
	Ownerships	7
	Ownership	1	37
	Ownership	2	12
	Ownership	3	43
	Ownership	4	18
	Ownership	5	59
	Ownership	6	74
	Ownership	7	39
	ReferencePrice	5
	StaticPriceBandLowerLimit	0.6
	StaticPriceBandUpperLimit	0.8
	TotalShares	100
	OwnershipUpperLimit	0.2
	TickSize	1
	LotSize	1
Limit	9	6	6	9	8	SELL	0	---	0
NewOrderRs	Accepted
	Trades	0
	Orders	5
	Order	Iceberg	2	7	2	4	6	SELL	0	---	1
	Order	Limit	1	3	4	5	4	SELL	0	---	0
	Order	Iceberg	3	6	3	7	4	SELL	0	---	4
	Order	Limit	6	5	1	7	6	SELL	0	---	0
	Order	Limit	9	6	6	9	8	SELL	0	---	0
	Credits	7
	Credit	1	6
	Credit	2	12
	Credit	3	9
	Credit	4	6
	Credit	5	16
	Credit	6	14
	Credit	7	7
	Ownerships	7
	Ownership	1	37
	Ownership	2	12
	Ownership	3	43
	Ownership	4	18
	Ownership	5	59
	Ownership	6	74
	Ownership	7	39
	ReferencePrice	5
	StaticPriceBandLowerLimit	0.6
	StaticPriceBandUpperLimit	0.8
	TotalShares	100
	OwnershipUpperLimit	0.2
	TickSize	1
	LotSize	1
Limit	10	6	6	1	7	SELL	0	---	0
ReplaceOrderRs	Rejected
	Trades	0
	Orders	5
	Order	Iceberg	2	7	2	4	6	SELL	0	---	1
	Order	Limit	1	3	4	5	4	SELL	0	---	0
	Order	Iceberg	3	6	3	7	4	SELL	0	---	4
	Order	Limit	6	5	1	7	6	SELL	0	---	0
	Order	Limit	9	6	6	9	8	SELL	0	---	0
	Credits	7
	Credit	1	6
	Credit	2	12
	Credit	3	9
	Credit	4	6
	Credit	5	16
	Credit	6	14
	Credit	7	7
	Ownerships	7
	Ownership	1	37
	Ownership	2	12
	Ownership	3	43
	Ownership	4	18
	Ownership	5	59
	Ownership	6	74
	Ownership	7	39
	ReferencePrice	5
	StaticPriceBandLowerLimit	0.6
	StaticPriceBandUpperLimit	0.8
	TotalShares	100
	OwnershipUpperLimit	0.2
	TickSize	1
	LotSize	1
Limit	11	3	6	7	1	SELL	1	---	0
NewOrderRs	Eliminated
	Trades	0
	Orders	5
	Order	Iceberg	2	7	2	4	6	SELL	0	---	1
	Order	Limit	1	3	4	5	4	SELL	0	---	0
	Order	Iceberg	3	6	3	7	4	SELL	0	---	4
	Order	Limit	6	5	1	7	6	SELL	0	---	0
	Order	Limit	9	6	6	9	8	SELL	0	---	0
	Credits	7
	Credit	1	6
	Credit	2	12
	Credit	3	9
	Credit	4	6
	Credit	5	16
	Credit	6	14
	Credit	7	7
	Ownerships	7
	Ownership	1	37
	Ownership	2	12
	Ownership	3	43
	Ownership	4	18
	Ownership	5	59
	Ownership	6	74
	Ownership	7	39
	ReferencePrice	5
	StaticPriceBandLowerLimit	0.6
	StaticPriceBandUpperLimit	0.8
	TotalShares	100
	OwnershipUpperLimit	0.2
	TickSize	1
	LotSize	1
Iceberg	12	7	1	7	7	SELL	0	---	0
NewOrderRs	Accepted
	Trades	0
	Orders	6
	Order	Iceberg	2	7	2	4	6	SELL	0	---	1
	Order	Limit	1	3	4	5	4	SELL	0	---	0
	Order	Iceberg	3	6	3	7	4	SELL	0	---	4
	Order	Limit	6	5	1	7	6	SELL	0	---	0
	Order	Iceberg	12	7	1	7	7	SELL	0	---	7
	Order	Limit	9	6	6	9	8	SELL	0	---	0
	Credits	7
	Credit	1	6
	Credit	2	12
	Credit	3	9
	Credit	4	6
	Credit	5	16
	Credit	6	14
	Credit	7	7
	Ownerships	7
	Ownership	1	37
	Ownership	2	12
	Ownership	3	43
	Ownership	4	18
	Ownership	5	59
	Ownership	6	74
	Ownership	7	39
	ReferencePrice	5
	StaticPriceBandLowerLimit	0.6
	StaticPriceBandUpperLimit	0.8
	TotalShares	100
	OwnershipUpperLimit	0.2
	TickSize	1
	LotSize	1
Iceberg	13	2	4	10	2	BUY 	1	---	0
NewOrderRs	Rejected
	Trades	0
	Orders	6
	Order	Iceberg	2	7	2	4	6	SELL	0	---	1
	Order	Limit	1	3	4	5	4	SELL	0	---	0
	Order	Iceberg	3	6	3	7	4	SELL	0	---	4
	Order	Limit	6	5	1	7	6	SELL	0	---	0
	Order	Iceberg	12	7	1	7	7	SELL	0	---	7
	Order	Limit	9	6	6	9	8	SELL	0	---	0
	Credits	7
	Credit	1	6
	Credit	2	12
	Credit	3	9
	Credit	4	6
	Credit	5	16
	Credit	6	14
	Credit	7	7
	Ownerships	7
	Ownership	1	37
	Ownership	2	12
	Ownership	3	43
	Ownership	4	18
	Ownership	5	59
	Ownership	6	74
	Ownership	7	39
	ReferencePrice	5
	StaticPriceBandLowerLimit	0.6
	StaticPriceBandUpperLimit	0.8
	TotalShares	100
	OwnershipUpperLimit	0.2
	TickSize	1
	LotSize	1
Iceberg	14	2	4	10	2	SELL	0	---	0
NewOrderRs	Rejected
	Trades	0
	Orders	6
	Order	Iceberg	2	7	2	4	6	SELL	0	---	1
	Order	Limit	1	3	4	5	4	SELL	0	---	0
	Order	Iceberg	3	6	3	7	4	SELL	0	---	4
	Order	Limit	6	5	1	7	6	SELL	0	---	0
	Order	Iceberg	12	7	1	7	7	SELL	0	---	7
	Order	Limit	9	6	6	9	8	SELL	0	---	0
	Credits	7
	Credit	1	6
	Credit	2	12
	Credit	3	9
	Credit	4	6
	Credit	5	16
	Credit	6	14
	Credit	7	7
