reported_result/report-8/ART_TFC/output/output8.txt

Iceberg	1	7	7	10	7	SELL	1	---	0
NewOrderRs	Rejected
	Trades	0
	Orders	0
	Credits	7
	Credit	1	10
	Credit	2	6
	Credit	3	11
	Credit	4	16
	Credit	5	6
	Credit	6	8
	Credit	7	14
	Ownerships	7
	Ownership	1	27
	Ownership	2	83
	Ownership	3	82
	Ownership	4	33
	Ownership	5	91
	Ownership	6	48
	Ownership	7	19
	ReferencePrice	5
	StaticPriceBandLowerLimit	0.6
	StaticPriceBandUpperLimit	0.8
	TotalShares	100
	OwnershipUpperLimit	0.2
	TickSize	1
	LotSize	1
Limit	2	3	4	3	5	SELL	0	---	0
NewOrderRs	Accepted
	Trades	0
	Orders	1
	Order	Limit	2	3	4	3	5	SELL	0	---	0
	Credits	7
	Credit	1	10
	Credit	2	6
	Credit	3	11
	Credit	4	16
	Credit	5	6
	Credit	6	8
	Credit	7	14
	Ownerships	7
	Ownership	1	27
	Ownership	2	83
	Ownership	3	82
	Ownership	4	33
	Ownership	5	91
	Ownership	6	48
	Ownership	7	19
	ReferencePrice	5
	StaticPriceBandLowerLimit	0.6
	StaticPriceBandUpperLimit	0.8
	TotalShares	100
	OwnershipUpperLimit	0.2
	TickSize	1
	LotSize	1
Limit	3	2	5	5	4	SELL	0	---	0
NewOrderRs	Accepted
	Trades	0
	Orders	2
	Order	Limit	2	3	4	3	5	SELL	0	---	0
	Order	Limit	3	2	5	5	4	SELL	0	---	0
	Credits	7
	Credit	1	10
	Credit	2	6
	Credit	3	11
	Credit	4	16
	Credit	5	6
	Credit	6	8
	Credit	7	14
	Ownerships	7
	Ownership	1	27
	Ownership	2	83
	Ownership	3	82
	Ownership	4	33
	Ownership	5	91
	Ownership	6	48
	Ownership	7	19
	ReferencePrice	5
	StaticPriceBandLowerLimit	0.6
	StaticPriceBandUpperLimit	0.8
	TotalShares	100
	OwnershipUpperLimit	0.2
	TickSize	1
	LotSize	1
Limit	4	7	6	6	2	SELL	0	FAK	0
NewOrderRs	Eliminated
	Trades	0
	Orders	2
	Order	Limit	2	3	4	3	5	SELL	0	---	0
	Order	Limit	3	2	5	5	4	SELL	0	---	0
	Credits	7
	Credit	1	10
	Credit	2	6
	Credit	3	11
	Credit	4	16
	Credit	5	6
	Credit	6	8
	Credit	7	14
	Ownerships	7
	Ownership	1	27
	Ownership	2	83
	Ownership	3	82
	Ownership	4	33
	Ownership	5	91
	Ownership	6	48
	Ownership	7	19
	ReferencePrice	5
	StaticPriceBandLowerLimit	0.6
	StaticPriceBandUpperLimit	0.8
	TotalShares	100
	OwnershipUpperLimit	0.2
	TickSize	1
	LotSize	1
CancelOrderRs	Rejected
	Orders	2
	Order	Limit	2	3	4	3	5	SELL	0	---	0
	Order	Limit	3	2	5	5	4	SELL	0	---	0
	Credits	7
	Credit	1	10
	Credit	2	6
	Credit	3	11
	Credit	4	16
	Credit	5	6
	Credit	6	8
	Credit	7	14
	Ownerships	7
	Ownership	1	27
	Ownership	2	83
	Ownership	3	82
	Ownership	4	33
	Ownership	5	91
	Ownership	6	48
	Ownership	7	19
	ReferencePrice	5
	StaticPriceBandLowerLimit	0.6
	StaticPriceBandUpperLimit	0.8
	TotalShares	100
	OwnershipUpperLimit	0.2
	TickSize	1
	LotSize	1
Limit	6	3	3	4	6	SELL	0	---	0
NewOrderRs	Accepted
	Trades	0
	Orders	3
	Order	Limit	2	3	4	3	5	SELL	0	---	0
	Order	Limit	6	3	3	4	6	SELL	0	---	0
	Order	Limit	3	2	5	5	4	SELL	0	---	0
	Credits	7
	Credit	1	10
	Credit	2	6
	Credit	3	11
	Credit	4	16
	Credit	5	6
	Credit	6	8
	Credit	7	14
	Ownerships	7
	Ownership	1	27
	Ownership	2	83
	Ownership	3	82
	Ownership	4	33
	Ownership	5	91
	Ownership	6	48
	Ownership	7	19
	ReferencePrice	5
	StaticPriceBandLowerLimit	0.6
	StaticPriceBandUpperLimit	0.8
	TotalShares	100
	OwnershipUpperLimit	0.2
	TickSize	1
	LotSize	1
Iceberg	7	7	7	3	8	SELL	2	---	0
NewOrderRs	Eliminated
	Trades	0
	Orders	3
	Order	Limit	2	3	4	3	5	SELL	0	---	0
	Order	Limit	6	3	3	4	6	SELL	0	---	0
	Order	Limit	3	2	5	5	4	SELL	0	---	0
	Credits	7
	Credit	1	10
	Credit	2	6
	Credit	3	11
	Credit	4	16
	Credit	5	6
	Credit	6	8
	Credit	7	14
	Ownerships	7
	Ownership	1	27
	Ownership	2	83
	Ownership	3	82
	Ownership	4	33
	Ownership	5	91
	Ownership	6	48
	Ownership	7	19
	ReferencePrice	5
	StaticPriceBandLowerLimit	0.6
	StaticPriceBandUpperLimit	0.8
	TotalShares	100
	OwnershipUpperLimit	0.2
	TickSize	1
	LotSize	1
Iceberg	8	3	4	1	3	SELL	0	---	0
NewOrderRs	Rejected
	Trades	0
	Orders	3
	Order	Limit	2	3	4	3	5	SELL	0	---	0
	Order	Limit	6	3	3	4	6	SELL	0	---	0
	Order	Limit	3	2	5	5	4	SELL	0	---	0
	Credits	7
	Credit	1	10
	Credit	2	6
	Credit	3	11
	Credit	4	16
	Credit	5	6
	Credit	6	8
	Credit	7	14
	Ownerships	7
	Ownership	1	27
	Ownership	2	83
	Ownership	3	82
	Ownership	4	33
	Ownership	5	91
	Ownership	6	48
	Ownership	7	19
	ReferencePrice	5
	StaticPriceBandLowerLimit	0.6
	StaticPriceBandUpperLimit	0.8
	TotalShares	100
	OwnershipUpperLimit	0.2
	TickSize	1
	LotSize	1
Limit	9	6	3	5	4	SELL	0	FAK	0
NewOrderRs	Eliminated
	Trades	0
	Orders	3
	Order	Limit	2	3	4	3	5	SELL	0	---	0
	Order	Limit	6	3	3	4	6	SELL	0	---	0
	Order	Limit	3	2	5	5	4	SELL	0	---	0
	Credits	7
	Credit	1	10
	Credit	2	6
	Credit	3	11
	Credit	4	16
	Credit	5	6
	Credit	6	8
	Credit	7	14
	Ownerships	7
	Ownership	1	27
	Ownership	2	83
	Ownership	3	82
	Ownership	4	33
	Ownership	5	91
	Ownership	6	48
	Ownership	7	19
	ReferencePrice	5
	StaticPriceBandLowerLimit	0.6
	StaticPriceBandUpperLimit	0.8
	TotalShares	100
	OwnershipUpperLimit	0.2
	TickSize	1
	LotSize	1
Limit	10	6	3	8	2	SELL	0	---	0
ReplaceOrderRs	Rejected
	Trades	0
	Orders	3
	Order	Limit	2	3	4	3	5	SELL	0	---	0
	Order	Limit	6	3	3	4	6	SELL	0	---	0
	Order	Limit	3	2	5	5	4	SELL	0	---	0
	Credits	7
	Credit	1	10
	Credit	2	6
	Credit	3	11
	Credit	4	16
	Credit	5	6
	Credit	6	8
	Credit	7	14
	Ownerships	7
	Ownership	1	27
	Ownership	2	83
	Ownership	3	82
	Ownership	4	33
	Ownership	5	91
	Ownership	6	48
	Ownership	7	19
	ReferencePrice	5
	StaticPriceBandLowerLimit	0.6
	StaticPriceBandUpperLimit	0.8
	TotalShares	100
	OwnershipUpperLimit	0.2
	TickSize	1
	LotSize	1
Limit	11	5	3	3	6	SELL	1	---	0
NewOrderRs	Eliminated
	Trades	0
	Orders	3
	Order	Limit	2	3	4	3	5	SELL	0	---	0
	Order	Limit	6	3	3	4	6	SELL	0	---	0
	Order	Limit	3	2	5	5	4	SELL	0	---	0
	Credits	7
	Credit	1	10
	Credit	2	6
	Credit	3	11
	Credit	4	16
	Credit	5	6
	Credit	6	8
	Credit	7	14
	Ownerships	7
	Ownership	1	27
	Ownership	2	83
	Ownership	3	82
	Ownership	4	33
	Ownership	5	91
	Ownership	6	48
	Ownership	7	19
	ReferencePrice	5
	StaticPriceBandLowerLimit	0.6
	StaticPriceBandUpperLimit	0.8
	TotalShares	100
	OwnershipUpperLimit	0.2
	TickSize	1
	LotSize	1
Limit	12	3	5	9	8	BUY 	0	FAK	0
NewOrderRs	Rejected
	Trades	0
	Orders	3
	Order	Limit	2	3	4	3	5	SELL	0	---	0
	Order	Limit	6	3	3	4	6	SELL	0	---	0
	Order	Limit	3	2	5	5	4	SELL	0	---	0
	Credits	7
	Credit	1	10
	Credit	2	6
	Credit	3	11
	Credit	4	16
	Credit	5	6
	Credit	6	8
	Credit	7	14
	Ownerships	7
	Ownership	1	27
	Ownership	2	83
	Ownership	3	82
	Ownership	4	33
	Ownership	5	91
	Ownership	6	48
	Ownership	7	19
	ReferencePrice	5
	StaticPriceBandLowerLimit	0.6
	StaticPriceBandUpperLimit	0.8
	TotalShares	100
	OwnershipUpperLimit	0.2
	TickSize	1
	LotSize	1
Limit	13	5	5	5	2	SELL	2	---	0
NewOrderRs	Eliminated
	Trades	0
	Orders	3
	Order	Limit	2	3	4	3	5	SELL	0	---	0
	Order	Limit	6	3	3	4	6	SELL	0	---	0
	Order	Limit	3	2	5	5	4	SELL	0	---	0
	Credits	7
	Credit	1	10
	Credit	2	6
	Credit	3	11
	Credit	4	16
	Credit	5	6
	Credit	6	8
	Credit	7	14
	Ownerships	7
	Ownership	1	27
	Ownership	2	83
	Ownership	3	82
	Ownership	4	33
	Ownership	5	91
	Ownership	6	48
	Ownership	7	19
	ReferencePrice	5
	StaticPriceBandLowerLimit	0.6
	StaticPriceBandUpperLimit	0.8
	TotalShares	100
	OwnershipUpperLimit	0.2
	TickSize	1
	LotSize	1
Iceberg	14	3	7	2	1	SELL	1	---	0
NewOrderRs	Eliminated
	Trades	0
	Orders	3
	Order	Limit	2	3	4	3	5	SELL	0	---	0
	Order	Limit	6	3	3	4	6	SELL	0	---	0
	Order	Limit	3	2	5	5	4	SELL	0	---	0
	Credits	7
	Credit	1	10
	Credit	2	6
	Credit	3	11
	Credit	4	16
	Credit	5	6
	Credit	6	8
	Credit	7	14
	Ownerships	7
	Ownership	1	27
	Ownership	2	83
	Ownership	3	82
	Ownership	4	33
	Ownership	5	91
	Ownership	6	48
	Ownership	7	19
	ReferencePrice	5
	StaticPriceBandLowerLimit	0.6
	StaticPriceBandUpperLimit	0.8
	TotalShares	100
	OwnershipUpperLimit	0.2
	TickSize	1
	LotSize	1
CancelOrderRs	Rejected
	Orders	3
	Order	Limit	2	3	4	3	5	SELL	0	---	0
	Order	Limit	6	3	3	4	6	SELL	0	---	0
	Order	Limit	3	2	5	5	4	SELL	0	---	0
	Credits	7
	Credit	1	10
	Credit	2	6
	Credit	3	11
	Credit	4	16
	Credit	5	6
	Credit	6	8
	Credit	7	14
	Ownerships	7
	Ownership	1	27
	Ownership	2	83
	Ownership	3	82
	Ownership	4	33
	Ownership	5	91
	Ownership	6	48
	Ownership	7	19
	ReferencePrice	5
	StaticPriceBandLowerLimit	0.6
	StaticPriceBandUpperLimit	0.8
	TotalShares	100
	OwnershipUpperLimit	0.2
	TickSize	1
	LotSize	1
Limit	16	1	6	7	3	SELL	0	---	0
NewOrderRs	Accepted
	Trades	0
	Orders	4
	Order	Limit	2	3	4	3	5	SELL	0	---	0
	Order	Limit	6	3	3	4	6	SELL	0	---	0
